FL Paper Experiment | INFO flwr 2024-04-17 13:37:58,983 | main.py:26 | 
================================================================================
FedFaces - FedAvg(accept_failures=True) - 3 clients - IID Distribution has started
================================================================================
FL Paper Experiment | INFO flwr 2024-04-17 13:37:58,984 | app.py:178 | Starting Flower simulation, config: num_rounds=20, no round_timeout
FL Paper Experiment | INFO flwr 2024-04-17 13:38:01,189 | app.py:213 | Flower VCE: Ray initialized with resources: {'node:__internal_head__': 1.0, 'CPU': 16.0, 'node:192.168.42.149': 1.0, 'object_store_memory': 9772824576.0, 'memory': 19545649152.0}
FL Paper Experiment | INFO flwr 2024-04-17 13:38:01,189 | app.py:219 | Optimize your simulation with Flower VCE: https://flower.ai/docs/framework/how-to-run-simulations.html
FL Paper Experiment | INFO flwr 2024-04-17 13:38:01,189 | app.py:242 | Flower VCE: Resources for each Virtual Client: {'num_cpus': 10, 'num_gpus': 0, 'memory': 3221225472}
FL Paper Experiment | INFO flwr 2024-04-17 13:38:01,210 | app.py:288 | Flower VCE: Creating VirtualClientEngineActorPool with 1 actors
FL Paper Experiment | INFO flwr 2024-04-17 13:38:01,210 | server.py:92 | [INIT]
FL Paper Experiment | INFO flwr 2024-04-17 13:38:01,210 | server.py:275 | Using initial global parameters provided by strategy
FL Paper Experiment | INFO flwr 2024-04-17 13:38:01,211 | server.py:94 | Evaluating initial global parameters
FL Paper Experiment | INFO flwr 2024-04-17 13:38:01,211 | server.py:110 | 
FL Paper Experiment | INFO flwr 2024-04-17 13:38:01,211 | server.py:111 | [ROUND 1]
FL Paper Experiment | INFO flwr 2024-04-17 13:38:01,211 | server.py:224 | configure_fit: strategy sampled 2 clients (out of 3)
FL Paper Experiment | INFO flwr 2024-04-17 13:38:43,924 | server.py:238 | aggregate_fit: received 2 results and 0 failures
FL Paper Experiment | WARNING flwr 2024-04-17 13:38:44,004 | fedavg.py:252 | No fit_metrics_aggregation_fn provided
FL Paper Experiment | INFO flwr 2024-04-17 13:38:44,005 | server.py:176 | configure_evaluate: strategy sampled 2 clients (out of 3)
FL Paper Experiment | ERROR flwr 2024-04-17 13:38:47,623 | ray_client_proxy.py:85 | Traceback (most recent call last):
  File "/home/debian/venv/lib/python3.11/site-packages/flwr/simulation/ray_transport/ray_client_proxy.py", line 73, in _submit_job
    out_mssg, updated_context = self.actor_pool.get_client_result(
                                ^^^^^^^^^^^^^^^^^^^^^^^^^^^^^^^^^^
  File "/home/debian/venv/lib/python3.11/site-packages/flwr/simulation/ray_transport/ray_actor.py", line 399, in get_client_result
    return self._fetch_future_result(cid)
           ^^^^^^^^^^^^^^^^^^^^^^^^^^^^^^
  File "/home/debian/venv/lib/python3.11/site-packages/flwr/simulation/ray_transport/ray_actor.py", line 280, in _fetch_future_result
    res_cid, out_mssg, updated_context = ray.get(
                                         ^^^^^^^^
  File "/home/debian/venv/lib/python3.11/site-packages/ray/_private/auto_init_hook.py", line 24, in auto_init_wrapper
    return fn(*args, **kwargs)
           ^^^^^^^^^^^^^^^^^^^
  File "/home/debian/venv/lib/python3.11/site-packages/ray/_private/client_mode_hook.py", line 103, in wrapper
    return func(*args, **kwargs)
           ^^^^^^^^^^^^^^^^^^^^^
  File "/home/debian/venv/lib/python3.11/site-packages/ray/_private/worker.py", line 2524, in get
    raise value.as_instanceof_cause()
ray.exceptions.RayTaskError(ClientAppException): [36mray::ClientAppActor.run()[39m (pid=339760, ip=192.168.42.149, actor_id=b532985f448aae5de27fd16c01000000, repr=<flwr.simulation.ray_transport.ray_actor.ClientAppActor object at 0x7f8f4c038350>)
                  ^^^^^^^^^^^^^^^^^^^^^^^^^^^^^^^^^^^^^
  File "/home/debian/venv/lib/python3.11/site-packages/flwr/client/client_app.py", line 98, in __call__
    return self._call(message, context)
           ^^^^^^^^^^^^^^^^^^^^^^^^^^^^
  File "/home/debian/venv/lib/python3.11/site-packages/flwr/client/client_app.py", line 81, in ffn
    out_message = handle_legacy_message_from_msgtype(
                  ^^^^^^^^^^^^^^^^^^^^^^^^^^^^^^^^^^^
  File "/home/debian/venv/lib/python3.11/site-packages/flwr/client/message_handler/message_handler.py", line 137, in handle_legacy_message_from_msgtype
    evaluate_res = maybe_call_evaluate(
                   ^^^^^^^^^^^^^^^^^^^^
  File "/home/debian/venv/lib/python3.11/site-packages/flwr/client/client.py", line 254, in maybe_call_evaluate
    return client.evaluate(evaluate_ins)
           ^^^^^^^^^^^^^^^^^^^^^^^^^^^^^
  File "/home/debian/venv/lib/python3.11/site-packages/flwr/client/numpy_client.py", line 262, in _evaluate
    results = self.numpy_client.evaluate(parameters, ins.config)  # type: ignore
              ^^^^^^^^^^^^^^^^^^^^^^^^^^^^^^^^^^^^^^^^^^^^^^^^^^
  File "/home/debian/Ethnicity-FL-paper/Clients.py", line 39, in evaluate
    PRINT("TEST REALLY RAN FINE")
    ^^^^^
NameError: name 'PRINT' is not defined

The above exception was the direct cause of the following exception:

[36mray::ClientAppActor.run()[39m (pid=339760, ip=192.168.42.149, actor_id=b532985f448aae5de27fd16c01000000, repr=<flwr.simulation.ray_transport.ray_actor.ClientAppActor object at 0x7f8f4c038350>)
           ^^^^^^^^^^^^^^^^^^^^^^^^^^^^^^^^^^^^
           ^^^^^^^^^^^^^^^^^^^^^^^^^^^^^^^
  File "/home/debian/venv/lib/python3.11/site-packages/flwr/simulation/ray_transport/ray_actor.py", line 64, in run
    raise ClientAppException(str(ex)) from ex
flwr.client.client_app.ClientAppException: 
Exception ClientAppException occurred. Message: name 'PRINT' is not defined

FL Paper Experiment | ERROR flwr 2024-04-17 13:38:47,626 | ray_client_proxy.py:86 | [36mray::ClientAppActor.run()[39m (pid=339760, ip=192.168.42.149, actor_id=b532985f448aae5de27fd16c01000000, repr=<flwr.simulation.ray_transport.ray_actor.ClientAppActor object at 0x7f8f4c038350>)
                  ^^^^^^^^^^^^^^^^^^^^^^^^^^^^^^^^^^^^^
  File "/home/debian/venv/lib/python3.11/site-packages/flwr/client/client_app.py", line 98, in __call__
    return self._call(message, context)
           ^^^^^^^^^^^^^^^^^^^^^^^^^^^^
  File "/home/debian/venv/lib/python3.11/site-packages/flwr/client/client_app.py", line 81, in ffn
    out_message = handle_legacy_message_from_msgtype(
                  ^^^^^^^^^^^^^^^^^^^^^^^^^^^^^^^^^^^
  File "/home/debian/venv/lib/python3.11/site-packages/flwr/client/message_handler/message_handler.py", line 137, in handle_legacy_message_from_msgtype
    evaluate_res = maybe_call_evaluate(
                   ^^^^^^^^^^^^^^^^^^^^
  File "/home/debian/venv/lib/python3.11/site-packages/flwr/client/client.py", line 254, in maybe_call_evaluate
    return client.evaluate(evaluate_ins)
           ^^^^^^^^^^^^^^^^^^^^^^^^^^^^^
  File "/home/debian/venv/lib/python3.11/site-packages/flwr/client/numpy_client.py", line 262, in _evaluate
    results = self.numpy_client.evaluate(parameters, ins.config)  # type: ignore
              ^^^^^^^^^^^^^^^^^^^^^^^^^^^^^^^^^^^^^^^^^^^^^^^^^^
  File "/home/debian/Ethnicity-FL-paper/Clients.py", line 39, in evaluate
    PRINT("TEST REALLY RAN FINE")
    ^^^^^
NameError: name 'PRINT' is not defined

The above exception was the direct cause of the following exception:

[36mray::ClientAppActor.run()[39m (pid=339760, ip=192.168.42.149, actor_id=b532985f448aae5de27fd16c01000000, repr=<flwr.simulation.ray_transport.ray_actor.ClientAppActor object at 0x7f8f4c038350>)
           ^^^^^^^^^^^^^^^^^^^^^^^^^^^^^^^^^^^^
           ^^^^^^^^^^^^^^^^^^^^^^^^^^^^^^^
  File "/home/debian/venv/lib/python3.11/site-packages/flwr/simulation/ray_transport/ray_actor.py", line 64, in run
    raise ClientAppException(str(ex)) from ex
flwr.client.client_app.ClientAppException: 
Exception ClientAppException occurred. Message: name 'PRINT' is not defined
FL Paper Experiment | ERROR flwr 2024-04-17 13:38:49,708 | ray_client_proxy.py:85 | Traceback (most recent call last):
  File "/home/debian/venv/lib/python3.11/site-packages/flwr/simulation/ray_transport/ray_client_proxy.py", line 73, in _submit_job
    out_mssg, updated_context = self.actor_pool.get_client_result(
                                ^^^^^^^^^^^^^^^^^^^^^^^^^^^^^^^^^^
  File "/home/debian/venv/lib/python3.11/site-packages/flwr/simulation/ray_transport/ray_actor.py", line 399, in get_client_result
    return self._fetch_future_result(cid)
           ^^^^^^^^^^^^^^^^^^^^^^^^^^^^^^
  File "/home/debian/venv/lib/python3.11/site-packages/flwr/simulation/ray_transport/ray_actor.py", line 280, in _fetch_future_result
    res_cid, out_mssg, updated_context = ray.get(
                                         ^^^^^^^^
  File "/home/debian/venv/lib/python3.11/site-packages/ray/_private/auto_init_hook.py", line 24, in auto_init_wrapper
    return fn(*args, **kwargs)
           ^^^^^^^^^^^^^^^^^^^
  File "/home/debian/venv/lib/python3.11/site-packages/ray/_private/client_mode_hook.py", line 103, in wrapper
    return func(*args, **kwargs)
           ^^^^^^^^^^^^^^^^^^^^^
  File "/home/debian/venv/lib/python3.11/site-packages/ray/_private/worker.py", line 2524, in get
    raise value.as_instanceof_cause()
ray.exceptions.RayTaskError(ClientAppException): [36mray::ClientAppActor.run()[39m (pid=339760, ip=192.168.42.149, actor_id=b532985f448aae5de27fd16c01000000, repr=<flwr.simulation.ray_transport.ray_actor.ClientAppActor object at 0x7f8f4c038350>)
                  ^^^^^^^^^^^^^^^^^^^^^^^^^^^^^^^^^^^^^
  File "/home/debian/venv/lib/python3.11/site-packages/flwr/client/client_app.py", line 98, in __call__
    return self._call(message, context)
           ^^^^^^^^^^^^^^^^^^^^^^^^^^^^
  File "/home/debian/venv/lib/python3.11/site-packages/flwr/client/client_app.py", line 81, in ffn
    out_message = handle_legacy_message_from_msgtype(
                  ^^^^^^^^^^^^^^^^^^^^^^^^^^^^^^^^^^^
  File "/home/debian/venv/lib/python3.11/site-packages/flwr/client/message_handler/message_handler.py", line 137, in handle_legacy_message_from_msgtype
    evaluate_res = maybe_call_evaluate(
                   ^^^^^^^^^^^^^^^^^^^^
  File "/home/debian/venv/lib/python3.11/site-packages/flwr/client/client.py", line 254, in maybe_call_evaluate
    return client.evaluate(evaluate_ins)
           ^^^^^^^^^^^^^^^^^^^^^^^^^^^^^
  File "/home/debian/venv/lib/python3.11/site-packages/flwr/client/numpy_client.py", line 262, in _evaluate
    results = self.numpy_client.evaluate(parameters, ins.config)  # type: ignore
              ^^^^^^^^^^^^^^^^^^^^^^^^^^^^^^^^^^^^^^^^^^^^^^^^^^
  File "/home/debian/Ethnicity-FL-paper/Clients.py", line 39, in evaluate
    PRINT("TEST REALLY RAN FINE")
    ^^^^^
NameError: name 'PRINT' is not defined

The above exception was the direct cause of the following exception:

[36mray::ClientAppActor.run()[39m (pid=339760, ip=192.168.42.149, actor_id=b532985f448aae5de27fd16c01000000, repr=<flwr.simulation.ray_transport.ray_actor.ClientAppActor object at 0x7f8f4c038350>)
           ^^^^^^^^^^^^^^^^^^^^^^^^^^^^^^^^^^^^
           ^^^^^^^^^^^^^^^^^^^^^^^^^^^^^^^
  File "/home/debian/venv/lib/python3.11/site-packages/flwr/simulation/ray_transport/ray_actor.py", line 64, in run
    raise ClientAppException(str(ex)) from ex
flwr.client.client_app.ClientAppException: 
Exception ClientAppException occurred. Message: name 'PRINT' is not defined

FL Paper Experiment | ERROR flwr 2024-04-17 13:38:49,709 | ray_client_proxy.py:86 | [36mray::ClientAppActor.run()[39m (pid=339760, ip=192.168.42.149, actor_id=b532985f448aae5de27fd16c01000000, repr=<flwr.simulation.ray_transport.ray_actor.ClientAppActor object at 0x7f8f4c038350>)
                  ^^^^^^^^^^^^^^^^^^^^^^^^^^^^^^^^^^^^^
  File "/home/debian/venv/lib/python3.11/site-packages/flwr/client/client_app.py", line 98, in __call__
    return self._call(message, context)
           ^^^^^^^^^^^^^^^^^^^^^^^^^^^^
  File "/home/debian/venv/lib/python3.11/site-packages/flwr/client/client_app.py", line 81, in ffn
    out_message = handle_legacy_message_from_msgtype(
                  ^^^^^^^^^^^^^^^^^^^^^^^^^^^^^^^^^^^
  File "/home/debian/venv/lib/python3.11/site-packages/flwr/client/message_handler/message_handler.py", line 137, in handle_legacy_message_from_msgtype
    evaluate_res = maybe_call_evaluate(
                   ^^^^^^^^^^^^^^^^^^^^
  File "/home/debian/venv/lib/python3.11/site-packages/flwr/client/client.py", line 254, in maybe_call_evaluate
    return client.evaluate(evaluate_ins)
           ^^^^^^^^^^^^^^^^^^^^^^^^^^^^^
  File "/home/debian/venv/lib/python3.11/site-packages/flwr/client/numpy_client.py", line 262, in _evaluate
    results = self.numpy_client.evaluate(parameters, ins.config)  # type: ignore
              ^^^^^^^^^^^^^^^^^^^^^^^^^^^^^^^^^^^^^^^^^^^^^^^^^^
  File "/home/debian/Ethnicity-FL-paper/Clients.py", line 39, in evaluate
    PRINT("TEST REALLY RAN FINE")
    ^^^^^
NameError: name 'PRINT' is not defined

The above exception was the direct cause of the following exception:

[36mray::ClientAppActor.run()[39m (pid=339760, ip=192.168.42.149, actor_id=b532985f448aae5de27fd16c01000000, repr=<flwr.simulation.ray_transport.ray_actor.ClientAppActor object at 0x7f8f4c038350>)
           ^^^^^^^^^^^^^^^^^^^^^^^^^^^^^^^^^^^^
           ^^^^^^^^^^^^^^^^^^^^^^^^^^^^^^^
  File "/home/debian/venv/lib/python3.11/site-packages/flwr/simulation/ray_transport/ray_actor.py", line 64, in run
    raise ClientAppException(str(ex)) from ex
flwr.client.client_app.ClientAppException: 
Exception ClientAppException occurred. Message: name 'PRINT' is not defined
FL Paper Experiment | INFO flwr 2024-04-17 13:38:49,709 | server.py:190 | aggregate_evaluate: received 0 results and 2 failures
FL Paper Experiment | INFO flwr 2024-04-17 13:38:49,710 | server.py:110 | 
FL Paper Experiment | INFO flwr 2024-04-17 13:38:49,710 | server.py:111 | [ROUND 2]
FL Paper Experiment | INFO flwr 2024-04-17 13:38:49,710 | server.py:224 | configure_fit: strategy sampled 2 clients (out of 3)
