FL Paper Experiment | INFO flwr 2024-03-19 14:21:00,203 | main.py:35 | 
================================================================================
CIFAR10 - FedProx - NonIID Distribution has started
================================================================================
FL Paper Experiment | INFO flwr 2024-03-19 14:21:00,204 | app.py:178 | Starting Flower simulation, config: ServerConfig(num_rounds=40, round_timeout=None)
FL Paper Experiment | INFO flwr 2024-03-19 14:21:02,202 | app.py:213 | Flower VCE: Ray initialized with resources: {'CPU': 6.0, 'node:172.18.144.40': 1.0, 'object_store_memory': 3700270694.0, 'memory': 7400541390.0, 'node:__internal_head__': 1.0}
FL Paper Experiment | INFO flwr 2024-03-19 14:21:02,204 | app.py:219 | Optimize your simulation with Flower VCE: https://flower.dev/docs/framework/how-to-run-simulations.html
FL Paper Experiment | INFO flwr 2024-03-19 14:21:02,205 | app.py:242 | Flower VCE: Resources for each Virtual Client: {'num_cpus': 4, 'num_gpus': 0}
FL Paper Experiment | INFO flwr 2024-03-19 14:21:02,211 | app.py:288 | Flower VCE: Creating VirtualClientEngineActorPool with 1 actors
FL Paper Experiment | INFO flwr 2024-03-19 14:21:02,212 | server.py:89 | Initializing global parameters
FL Paper Experiment | INFO flwr 2024-03-19 14:21:02,213 | server.py:276 | Requesting initial parameters from one random client
FL Paper Experiment | INFO flwr 2024-03-19 14:21:04,941 | server.py:280 | Received initial parameters from one random client
FL Paper Experiment | INFO flwr 2024-03-19 14:21:04,942 | server.py:91 | Evaluating initial parameters
FL Paper Experiment | INFO flwr 2024-03-19 14:21:04,942 | server.py:104 | FL starting
FL Paper Experiment | DEBUG flwr 2024-03-19 14:21:04,943 | server.py:222 | fit_round 1: strategy sampled 10 clients (out of 20)
FL Paper Experiment | DEBUG flwr 2024-03-19 14:32:05,561 | server.py:236 | fit_round 1 received 10 results and 0 failures
FL Paper Experiment | WARNING flwr 2024-03-19 14:32:06,954 | fedavg.py:250 | No fit_metrics_aggregation_fn provided
FL Paper Experiment | DEBUG flwr 2024-03-19 14:32:06,961 | server.py:173 | evaluate_round 1: strategy sampled 10 clients (out of 20)
FL Paper Experiment | ERROR flwr 2024-03-19 14:32:08,620 | ray_client_proxy.py:161 | Traceback (most recent call last):
  File "/home/leon/.local/lib/python3.10/site-packages/flwr/simulation/ray_transport/ray_client_proxy.py", line 151, in _submit_job
    res, updated_context = self.actor_pool.get_client_result(self.cid, timeout)
  File "/home/leon/.local/lib/python3.10/site-packages/flwr/simulation/ray_transport/ray_actor.py", line 425, in get_client_result
    return self._fetch_future_result(cid)
  File "/home/leon/.local/lib/python3.10/site-packages/flwr/simulation/ray_transport/ray_actor.py", line 306, in _fetch_future_result
    res_cid, res, updated_context = ray.get(
  File "/home/leon/.local/lib/python3.10/site-packages/ray/_private/auto_init_hook.py", line 24, in auto_init_wrapper
    return fn(*args, **kwargs)
  File "/home/leon/.local/lib/python3.10/site-packages/ray/_private/client_mode_hook.py", line 103, in wrapper
    return func(*args, **kwargs)
  File "/home/leon/.local/lib/python3.10/site-packages/ray/_private/worker.py", line 2524, in get
    raise value.as_instanceof_cause()
ray.exceptions.RayTaskError(ClientException): [36mray::DefaultActor.run()[39m (pid=3898, ip=172.18.144.40, actor_id=efb862ab5f73b1f2b5b4ec9f01000000, repr=<flwr.simulation.ray_transport.ray_actor.DefaultActor object at 0x7f3f30dc6710>)
  File "/home/leon/.local/lib/python3.10/site-packages/flwr/simulation/ray_transport/ray_client_proxy.py", line 225, in evaluate
    return maybe_call_evaluate(
  File "/home/leon/.local/lib/python3.10/site-packages/flwr/client/client.py", line 254, in maybe_call_evaluate
    return client.evaluate(evaluate_ins)
  File "/home/leon/.local/lib/python3.10/site-packages/flwr/client/numpy_client.py", line 262, in _evaluate
    results = self.numpy_client.evaluate(parameters, ins.config)  # type: ignore
  File "/mnt/c/Users/leon1/Documents/Research Repo/Experiments/Ethnicity FL paper/Clients.py", line 36, in evaluate
    loss, accuracy, f1, roc, kappa = test(self.net, self.valloader, DEVICE=self.device, classes=self.net.classes)
  File "/mnt/c/Users/leon1/Documents/Research Repo/Experiments/Ethnicity FL paper/neural_nets.py", line 139, in test
    kappa += multiclass_cohen_kappa(preds, target, num_classes=3)
NameError: name 'preds' is not defined

The above exception was the direct cause of the following exception:

[36mray::DefaultActor.run()[39m (pid=3898, ip=172.18.144.40, actor_id=efb862ab5f73b1f2b5b4ec9f01000000, repr=<flwr.simulation.ray_transport.ray_actor.DefaultActor object at 0x7f3f30dc6710>)
  File "/home/leon/.local/lib/python3.10/site-packages/flwr/simulation/ray_transport/ray_actor.py", line 90, in run
    raise ClientException(str(message)) from ex
flwr.simulation.ray_transport.ray_actor.ClientException: 
>>>>>>>A ClientException occurred.('\n\tSomething went wrong when running your client run.\n\tClient 12 crashed when the DefaultActor was running its run.\n\tException triggered on the client side: Traceback (most recent call last):\n  File "/home/leon/.local/lib/python3.10/site-packages/flwr/simulation/ray_transport/ray_actor.py", line 76, in run\n    job_results = job_fn(client)\n  File "/home/leon/.local/lib/python3.10/site-packages/flwr/simulation/ray_transport/ray_client_proxy.py", line 225, in evaluate\n    return maybe_call_evaluate(\n  File "/home/leon/.local/lib/python3.10/site-packages/flwr/client/client.py", line 254, in maybe_call_evaluate\n    return client.evaluate(evaluate_ins)\n  File "/home/leon/.local/lib/python3.10/site-packages/flwr/client/numpy_client.py", line 262, in _evaluate\n    results = self.numpy_client.evaluate(parameters, ins.config)  # type: ignore\n  File "/mnt/c/Users/leon1/Documents/Research Repo/Experiments/Ethnicity FL paper/Clients.py", line 36, in evaluate\n    loss, accuracy, f1, roc, kappa = test(self.net, self.valloader, DEVICE=self.device, classes=self.net.classes)\n  File "/mnt/c/Users/leon1/Documents/Research Repo/Experiments/Ethnicity FL paper/neural_nets.py", line 139, in test\n    kappa += multiclass_cohen_kappa(preds, target, num_classes=3)\nNameError: name \'preds\' is not defined\n',)

FL Paper Experiment | ERROR flwr 2024-03-19 14:32:08,621 | ray_client_proxy.py:162 | [36mray::DefaultActor.run()[39m (pid=3898, ip=172.18.144.40, actor_id=efb862ab5f73b1f2b5b4ec9f01000000, repr=<flwr.simulation.ray_transport.ray_actor.DefaultActor object at 0x7f3f30dc6710>)
  File "/home/leon/.local/lib/python3.10/site-packages/flwr/simulation/ray_transport/ray_client_proxy.py", line 225, in evaluate
    return maybe_call_evaluate(
  File "/home/leon/.local/lib/python3.10/site-packages/flwr/client/client.py", line 254, in maybe_call_evaluate
    return client.evaluate(evaluate_ins)
  File "/home/leon/.local/lib/python3.10/site-packages/flwr/client/numpy_client.py", line 262, in _evaluate
    results = self.numpy_client.evaluate(parameters, ins.config)  # type: ignore
  File "/mnt/c/Users/leon1/Documents/Research Repo/Experiments/Ethnicity FL paper/Clients.py", line 36, in evaluate
    loss, accuracy, f1, roc, kappa = test(self.net, self.valloader, DEVICE=self.device, classes=self.net.classes)
  File "/mnt/c/Users/leon1/Documents/Research Repo/Experiments/Ethnicity FL paper/neural_nets.py", line 139, in test
    kappa += multiclass_cohen_kappa(preds, target, num_classes=3)
NameError: name 'preds' is not defined

The above exception was the direct cause of the following exception:

[36mray::DefaultActor.run()[39m (pid=3898, ip=172.18.144.40, actor_id=efb862ab5f73b1f2b5b4ec9f01000000, repr=<flwr.simulation.ray_transport.ray_actor.DefaultActor object at 0x7f3f30dc6710>)
  File "/home/leon/.local/lib/python3.10/site-packages/flwr/simulation/ray_transport/ray_actor.py", line 90, in run
    raise ClientException(str(message)) from ex
flwr.simulation.ray_transport.ray_actor.ClientException: 
>>>>>>>A ClientException occurred.('\n\tSomething went wrong when running your client run.\n\tClient 12 crashed when the DefaultActor was running its run.\n\tException triggered on the client side: Traceback (most recent call last):\n  File "/home/leon/.local/lib/python3.10/site-packages/flwr/simulation/ray_transport/ray_actor.py", line 76, in run\n    job_results = job_fn(client)\n  File "/home/leon/.local/lib/python3.10/site-packages/flwr/simulation/ray_transport/ray_client_proxy.py", line 225, in evaluate\n    return maybe_call_evaluate(\n  File "/home/leon/.local/lib/python3.10/site-packages/flwr/client/client.py", line 254, in maybe_call_evaluate\n    return client.evaluate(evaluate_ins)\n  File "/home/leon/.local/lib/python3.10/site-packages/flwr/client/numpy_client.py", line 262, in _evaluate\n    results = self.numpy_client.evaluate(parameters, ins.config)  # type: ignore\n  File "/mnt/c/Users/leon1/Documents/Research Repo/Experiments/Ethnicity FL paper/Clients.py", line 36, in evaluate\n    loss, accuracy, f1, roc, kappa = test(self.net, self.valloader, DEVICE=self.device, classes=self.net.classes)\n  File "/mnt/c/Users/leon1/Documents/Research Repo/Experiments/Ethnicity FL paper/neural_nets.py", line 139, in test\n    kappa += multiclass_cohen_kappa(preds, target, num_classes=3)\nNameError: name \'preds\' is not defined\n',)
FL Paper Experiment | ERROR flwr 2024-03-19 14:32:09,410 | ray_client_proxy.py:161 | Traceback (most recent call last):
  File "/home/leon/.local/lib/python3.10/site-packages/flwr/simulation/ray_transport/ray_client_proxy.py", line 151, in _submit_job
    res, updated_context = self.actor_pool.get_client_result(self.cid, timeout)
  File "/home/leon/.local/lib/python3.10/site-packages/flwr/simulation/ray_transport/ray_actor.py", line 425, in get_client_result
    return self._fetch_future_result(cid)
  File "/home/leon/.local/lib/python3.10/site-packages/flwr/simulation/ray_transport/ray_actor.py", line 306, in _fetch_future_result
    res_cid, res, updated_context = ray.get(
  File "/home/leon/.local/lib/python3.10/site-packages/ray/_private/auto_init_hook.py", line 24, in auto_init_wrapper
    return fn(*args, **kwargs)
  File "/home/leon/.local/lib/python3.10/site-packages/ray/_private/client_mode_hook.py", line 103, in wrapper
    return func(*args, **kwargs)
  File "/home/leon/.local/lib/python3.10/site-packages/ray/_private/worker.py", line 2524, in get
    raise value.as_instanceof_cause()
ray.exceptions.RayTaskError(ClientException): [36mray::DefaultActor.run()[39m (pid=3898, ip=172.18.144.40, actor_id=efb862ab5f73b1f2b5b4ec9f01000000, repr=<flwr.simulation.ray_transport.ray_actor.DefaultActor object at 0x7f3f30dc6710>)
  File "/home/leon/.local/lib/python3.10/site-packages/flwr/simulation/ray_transport/ray_client_proxy.py", line 225, in evaluate
    return maybe_call_evaluate(
  File "/home/leon/.local/lib/python3.10/site-packages/flwr/client/client.py", line 254, in maybe_call_evaluate
    return client.evaluate(evaluate_ins)
  File "/home/leon/.local/lib/python3.10/site-packages/flwr/client/numpy_client.py", line 262, in _evaluate
    results = self.numpy_client.evaluate(parameters, ins.config)  # type: ignore
  File "/mnt/c/Users/leon1/Documents/Research Repo/Experiments/Ethnicity FL paper/Clients.py", line 36, in evaluate
    loss, accuracy, f1, roc, kappa = test(self.net, self.valloader, DEVICE=self.device, classes=self.net.classes)
  File "/mnt/c/Users/leon1/Documents/Research Repo/Experiments/Ethnicity FL paper/neural_nets.py", line 139, in test
    kappa += multiclass_cohen_kappa(preds, target, num_classes=3)
NameError: name 'preds' is not defined

The above exception was the direct cause of the following exception:

[36mray::DefaultActor.run()[39m (pid=3898, ip=172.18.144.40, actor_id=efb862ab5f73b1f2b5b4ec9f01000000, repr=<flwr.simulation.ray_transport.ray_actor.DefaultActor object at 0x7f3f30dc6710>)
  File "/home/leon/.local/lib/python3.10/site-packages/flwr/simulation/ray_transport/ray_actor.py", line 90, in run
    raise ClientException(str(message)) from ex
flwr.simulation.ray_transport.ray_actor.ClientException: 
>>>>>>>A ClientException occurred.('\n\tSomething went wrong when running your client run.\n\tClient 9 crashed when the DefaultActor was running its run.\n\tException triggered on the client side: Traceback (most recent call last):\n  File "/home/leon/.local/lib/python3.10/site-packages/flwr/simulation/ray_transport/ray_actor.py", line 76, in run\n    job_results = job_fn(client)\n  File "/home/leon/.local/lib/python3.10/site-packages/flwr/simulation/ray_transport/ray_client_proxy.py", line 225, in evaluate\n    return maybe_call_evaluate(\n  File "/home/leon/.local/lib/python3.10/site-packages/flwr/client/client.py", line 254, in maybe_call_evaluate\n    return client.evaluate(evaluate_ins)\n  File "/home/leon/.local/lib/python3.10/site-packages/flwr/client/numpy_client.py", line 262, in _evaluate\n    results = self.numpy_client.evaluate(parameters, ins.config)  # type: ignore\n  File "/mnt/c/Users/leon1/Documents/Research Repo/Experiments/Ethnicity FL paper/Clients.py", line 36, in evaluate\n    loss, accuracy, f1, roc, kappa = test(self.net, self.valloader, DEVICE=self.device, classes=self.net.classes)\n  File "/mnt/c/Users/leon1/Documents/Research Repo/Experiments/Ethnicity FL paper/neural_nets.py", line 139, in test\n    kappa += multiclass_cohen_kappa(preds, target, num_classes=3)\nNameError: name \'preds\' is not defined\n',)

FL Paper Experiment | ERROR flwr 2024-03-19 14:32:09,412 | ray_client_proxy.py:162 | [36mray::DefaultActor.run()[39m (pid=3898, ip=172.18.144.40, actor_id=efb862ab5f73b1f2b5b4ec9f01000000, repr=<flwr.simulation.ray_transport.ray_actor.DefaultActor object at 0x7f3f30dc6710>)
  File "/home/leon/.local/lib/python3.10/site-packages/flwr/simulation/ray_transport/ray_client_proxy.py", line 225, in evaluate
    return maybe_call_evaluate(
  File "/home/leon/.local/lib/python3.10/site-packages/flwr/client/client.py", line 254, in maybe_call_evaluate
    return client.evaluate(evaluate_ins)
  File "/home/leon/.local/lib/python3.10/site-packages/flwr/client/numpy_client.py", line 262, in _evaluate
    results = self.numpy_client.evaluate(parameters, ins.config)  # type: ignore
  File "/mnt/c/Users/leon1/Documents/Research Repo/Experiments/Ethnicity FL paper/Clients.py", line 36, in evaluate
    loss, accuracy, f1, roc, kappa = test(self.net, self.valloader, DEVICE=self.device, classes=self.net.classes)
  File "/mnt/c/Users/leon1/Documents/Research Repo/Experiments/Ethnicity FL paper/neural_nets.py", line 139, in test
    kappa += multiclass_cohen_kappa(preds, target, num_classes=3)
NameError: name 'preds' is not defined

The above exception was the direct cause of the following exception:

[36mray::DefaultActor.run()[39m (pid=3898, ip=172.18.144.40, actor_id=efb862ab5f73b1f2b5b4ec9f01000000, repr=<flwr.simulation.ray_transport.ray_actor.DefaultActor object at 0x7f3f30dc6710>)
  File "/home/leon/.local/lib/python3.10/site-packages/flwr/simulation/ray_transport/ray_actor.py", line 90, in run
    raise ClientException(str(message)) from ex
flwr.simulation.ray_transport.ray_actor.ClientException: 
>>>>>>>A ClientException occurred.('\n\tSomething went wrong when running your client run.\n\tClient 9 crashed when the DefaultActor was running its run.\n\tException triggered on the client side: Traceback (most recent call last):\n  File "/home/leon/.local/lib/python3.10/site-packages/flwr/simulation/ray_transport/ray_actor.py", line 76, in run\n    job_results = job_fn(client)\n  File "/home/leon/.local/lib/python3.10/site-packages/flwr/simulation/ray_transport/ray_client_proxy.py", line 225, in evaluate\n    return maybe_call_evaluate(\n  File "/home/leon/.local/lib/python3.10/site-packages/flwr/client/client.py", line 254, in maybe_call_evaluate\n    return client.evaluate(evaluate_ins)\n  File "/home/leon/.local/lib/python3.10/site-packages/flwr/client/numpy_client.py", line 262, in _evaluate\n    results = self.numpy_client.evaluate(parameters, ins.config)  # type: ignore\n  File "/mnt/c/Users/leon1/Documents/Research Repo/Experiments/Ethnicity FL paper/Clients.py", line 36, in evaluate\n    loss, accuracy, f1, roc, kappa = test(self.net, self.valloader, DEVICE=self.device, classes=self.net.classes)\n  File "/mnt/c/Users/leon1/Documents/Research Repo/Experiments/Ethnicity FL paper/neural_nets.py", line 139, in test\n    kappa += multiclass_cohen_kappa(preds, target, num_classes=3)\nNameError: name \'preds\' is not defined\n',)
FL Paper Experiment | ERROR flwr 2024-03-19 14:32:10,116 | ray_client_proxy.py:161 | Traceback (most recent call last):
  File "/home/leon/.local/lib/python3.10/site-packages/flwr/simulation/ray_transport/ray_client_proxy.py", line 151, in _submit_job
    res, updated_context = self.actor_pool.get_client_result(self.cid, timeout)
  File "/home/leon/.local/lib/python3.10/site-packages/flwr/simulation/ray_transport/ray_actor.py", line 425, in get_client_result
    return self._fetch_future_result(cid)
  File "/home/leon/.local/lib/python3.10/site-packages/flwr/simulation/ray_transport/ray_actor.py", line 306, in _fetch_future_result
    res_cid, res, updated_context = ray.get(
  File "/home/leon/.local/lib/python3.10/site-packages/ray/_private/auto_init_hook.py", line 24, in auto_init_wrapper
    return fn(*args, **kwargs)
  File "/home/leon/.local/lib/python3.10/site-packages/ray/_private/client_mode_hook.py", line 103, in wrapper
    return func(*args, **kwargs)
  File "/home/leon/.local/lib/python3.10/site-packages/ray/_private/worker.py", line 2524, in get
    raise value.as_instanceof_cause()
ray.exceptions.RayTaskError(ClientException): [36mray::DefaultActor.run()[39m (pid=3898, ip=172.18.144.40, actor_id=efb862ab5f73b1f2b5b4ec9f01000000, repr=<flwr.simulation.ray_transport.ray_actor.DefaultActor object at 0x7f3f30dc6710>)
  File "/home/leon/.local/lib/python3.10/site-packages/flwr/simulation/ray_transport/ray_client_proxy.py", line 225, in evaluate
    return maybe_call_evaluate(
  File "/home/leon/.local/lib/python3.10/site-packages/flwr/client/client.py", line 254, in maybe_call_evaluate
    return client.evaluate(evaluate_ins)
  File "/home/leon/.local/lib/python3.10/site-packages/flwr/client/numpy_client.py", line 262, in _evaluate
    results = self.numpy_client.evaluate(parameters, ins.config)  # type: ignore
  File "/mnt/c/Users/leon1/Documents/Research Repo/Experiments/Ethnicity FL paper/Clients.py", line 36, in evaluate
    loss, accuracy, f1, roc, kappa = test(self.net, self.valloader, DEVICE=self.device, classes=self.net.classes)
  File "/mnt/c/Users/leon1/Documents/Research Repo/Experiments/Ethnicity FL paper/neural_nets.py", line 139, in test
    kappa += multiclass_cohen_kappa(preds, target, num_classes=3)
NameError: name 'preds' is not defined

The above exception was the direct cause of the following exception:

[36mray::DefaultActor.run()[39m (pid=3898, ip=172.18.144.40, actor_id=efb862ab5f73b1f2b5b4ec9f01000000, repr=<flwr.simulation.ray_transport.ray_actor.DefaultActor object at 0x7f3f30dc6710>)
  File "/home/leon/.local/lib/python3.10/site-packages/flwr/simulation/ray_transport/ray_actor.py", line 90, in run
    raise ClientException(str(message)) from ex
flwr.simulation.ray_transport.ray_actor.ClientException: 
>>>>>>>A ClientException occurred.('\n\tSomething went wrong when running your client run.\n\tClient 4 crashed when the DefaultActor was running its run.\n\tException triggered on the client side: Traceback (most recent call last):\n  File "/home/leon/.local/lib/python3.10/site-packages/flwr/simulation/ray_transport/ray_actor.py", line 76, in run\n    job_results = job_fn(client)\n  File "/home/leon/.local/lib/python3.10/site-packages/flwr/simulation/ray_transport/ray_client_proxy.py", line 225, in evaluate\n    return maybe_call_evaluate(\n  File "/home/leon/.local/lib/python3.10/site-packages/flwr/client/client.py", line 254, in maybe_call_evaluate\n    return client.evaluate(evaluate_ins)\n  File "/home/leon/.local/lib/python3.10/site-packages/flwr/client/numpy_client.py", line 262, in _evaluate\n    results = self.numpy_client.evaluate(parameters, ins.config)  # type: ignore\n  File "/mnt/c/Users/leon1/Documents/Research Repo/Experiments/Ethnicity FL paper/Clients.py", line 36, in evaluate\n    loss, accuracy, f1, roc, kappa = test(self.net, self.valloader, DEVICE=self.device, classes=self.net.classes)\n  File "/mnt/c/Users/leon1/Documents/Research Repo/Experiments/Ethnicity FL paper/neural_nets.py", line 139, in test\n    kappa += multiclass_cohen_kappa(preds, target, num_classes=3)\nNameError: name \'preds\' is not defined\n',)

FL Paper Experiment | ERROR flwr 2024-03-19 14:32:10,117 | ray_client_proxy.py:162 | [36mray::DefaultActor.run()[39m (pid=3898, ip=172.18.144.40, actor_id=efb862ab5f73b1f2b5b4ec9f01000000, repr=<flwr.simulation.ray_transport.ray_actor.DefaultActor object at 0x7f3f30dc6710>)
  File "/home/leon/.local/lib/python3.10/site-packages/flwr/simulation/ray_transport/ray_client_proxy.py", line 225, in evaluate
    return maybe_call_evaluate(
  File "/home/leon/.local/lib/python3.10/site-packages/flwr/client/client.py", line 254, in maybe_call_evaluate
    return client.evaluate(evaluate_ins)
  File "/home/leon/.local/lib/python3.10/site-packages/flwr/client/numpy_client.py", line 262, in _evaluate
    results = self.numpy_client.evaluate(parameters, ins.config)  # type: ignore
  File "/mnt/c/Users/leon1/Documents/Research Repo/Experiments/Ethnicity FL paper/Clients.py", line 36, in evaluate
    loss, accuracy, f1, roc, kappa = test(self.net, self.valloader, DEVICE=self.device, classes=self.net.classes)
  File "/mnt/c/Users/leon1/Documents/Research Repo/Experiments/Ethnicity FL paper/neural_nets.py", line 139, in test
    kappa += multiclass_cohen_kappa(preds, target, num_classes=3)
NameError: name 'preds' is not defined

The above exception was the direct cause of the following exception:

[36mray::DefaultActor.run()[39m (pid=3898, ip=172.18.144.40, actor_id=efb862ab5f73b1f2b5b4ec9f01000000, repr=<flwr.simulation.ray_transport.ray_actor.DefaultActor object at 0x7f3f30dc6710>)
  File "/home/leon/.local/lib/python3.10/site-packages/flwr/simulation/ray_transport/ray_actor.py", line 90, in run
    raise ClientException(str(message)) from ex
flwr.simulation.ray_transport.ray_actor.ClientException: 
>>>>>>>A ClientException occurred.('\n\tSomething went wrong when running your client run.\n\tClient 4 crashed when the DefaultActor was running its run.\n\tException triggered on the client side: Traceback (most recent call last):\n  File "/home/leon/.local/lib/python3.10/site-packages/flwr/simulation/ray_transport/ray_actor.py", line 76, in run\n    job_results = job_fn(client)\n  File "/home/leon/.local/lib/python3.10/site-packages/flwr/simulation/ray_transport/ray_client_proxy.py", line 225, in evaluate\n    return maybe_call_evaluate(\n  File "/home/leon/.local/lib/python3.10/site-packages/flwr/client/client.py", line 254, in maybe_call_evaluate\n    return client.evaluate(evaluate_ins)\n  File "/home/leon/.local/lib/python3.10/site-packages/flwr/client/numpy_client.py", line 262, in _evaluate\n    results = self.numpy_client.evaluate(parameters, ins.config)  # type: ignore\n  File "/mnt/c/Users/leon1/Documents/Research Repo/Experiments/Ethnicity FL paper/Clients.py", line 36, in evaluate\n    loss, accuracy, f1, roc, kappa = test(self.net, self.valloader, DEVICE=self.device, classes=self.net.classes)\n  File "/mnt/c/Users/leon1/Documents/Research Repo/Experiments/Ethnicity FL paper/neural_nets.py", line 139, in test\n    kappa += multiclass_cohen_kappa(preds, target, num_classes=3)\nNameError: name \'preds\' is not defined\n',)
FL Paper Experiment | ERROR flwr 2024-03-19 14:32:11,150 | ray_client_proxy.py:161 | Traceback (most recent call last):
  File "/home/leon/.local/lib/python3.10/site-packages/flwr/simulation/ray_transport/ray_client_proxy.py", line 151, in _submit_job
    res, updated_context = self.actor_pool.get_client_result(self.cid, timeout)
  File "/home/leon/.local/lib/python3.10/site-packages/flwr/simulation/ray_transport/ray_actor.py", line 425, in get_client_result
    return self._fetch_future_result(cid)
  File "/home/leon/.local/lib/python3.10/site-packages/flwr/simulation/ray_transport/ray_actor.py", line 306, in _fetch_future_result
    res_cid, res, updated_context = ray.get(
  File "/home/leon/.local/lib/python3.10/site-packages/ray/_private/auto_init_hook.py", line 24, in auto_init_wrapper
    return fn(*args, **kwargs)
  File "/home/leon/.local/lib/python3.10/site-packages/ray/_private/client_mode_hook.py", line 103, in wrapper
    return func(*args, **kwargs)
  File "/home/leon/.local/lib/python3.10/site-packages/ray/_private/worker.py", line 2524, in get
    raise value.as_instanceof_cause()
ray.exceptions.RayTaskError(ClientException): [36mray::DefaultActor.run()[39m (pid=3898, ip=172.18.144.40, actor_id=efb862ab5f73b1f2b5b4ec9f01000000, repr=<flwr.simulation.ray_transport.ray_actor.DefaultActor object at 0x7f3f30dc6710>)
  File "/home/leon/.local/lib/python3.10/site-packages/flwr/simulation/ray_transport/ray_client_proxy.py", line 225, in evaluate
    return maybe_call_evaluate(
  File "/home/leon/.local/lib/python3.10/site-packages/flwr/client/client.py", line 254, in maybe_call_evaluate
    return client.evaluate(evaluate_ins)
  File "/home/leon/.local/lib/python3.10/site-packages/flwr/client/numpy_client.py", line 262, in _evaluate
    results = self.numpy_client.evaluate(parameters, ins.config)  # type: ignore
  File "/mnt/c/Users/leon1/Documents/Research Repo/Experiments/Ethnicity FL paper/Clients.py", line 36, in evaluate
    loss, accuracy, f1, roc, kappa = test(self.net, self.valloader, DEVICE=self.device, classes=self.net.classes)
  File "/mnt/c/Users/leon1/Documents/Research Repo/Experiments/Ethnicity FL paper/neural_nets.py", line 139, in test
    kappa += multiclass_cohen_kappa(preds, target, num_classes=3)
NameError: name 'preds' is not defined

The above exception was the direct cause of the following exception:

[36mray::DefaultActor.run()[39m (pid=3898, ip=172.18.144.40, actor_id=efb862ab5f73b1f2b5b4ec9f01000000, repr=<flwr.simulation.ray_transport.ray_actor.DefaultActor object at 0x7f3f30dc6710>)
  File "/home/leon/.local/lib/python3.10/site-packages/flwr/simulation/ray_transport/ray_actor.py", line 90, in run
    raise ClientException(str(message)) from ex
flwr.simulation.ray_transport.ray_actor.ClientException: 
>>>>>>>A ClientException occurred.('\n\tSomething went wrong when running your client run.\n\tClient 3 crashed when the DefaultActor was running its run.\n\tException triggered on the client side: Traceback (most recent call last):\n  File "/home/leon/.local/lib/python3.10/site-packages/flwr/simulation/ray_transport/ray_actor.py", line 76, in run\n    job_results = job_fn(client)\n  File "/home/leon/.local/lib/python3.10/site-packages/flwr/simulation/ray_transport/ray_client_proxy.py", line 225, in evaluate\n    return maybe_call_evaluate(\n  File "/home/leon/.local/lib/python3.10/site-packages/flwr/client/client.py", line 254, in maybe_call_evaluate\n    return client.evaluate(evaluate_ins)\n  File "/home/leon/.local/lib/python3.10/site-packages/flwr/client/numpy_client.py", line 262, in _evaluate\n    results = self.numpy_client.evaluate(parameters, ins.config)  # type: ignore\n  File "/mnt/c/Users/leon1/Documents/Research Repo/Experiments/Ethnicity FL paper/Clients.py", line 36, in evaluate\n    loss, accuracy, f1, roc, kappa = test(self.net, self.valloader, DEVICE=self.device, classes=self.net.classes)\n  File "/mnt/c/Users/leon1/Documents/Research Repo/Experiments/Ethnicity FL paper/neural_nets.py", line 139, in test\n    kappa += multiclass_cohen_kappa(preds, target, num_classes=3)\nNameError: name \'preds\' is not defined\n',)

FL Paper Experiment | ERROR flwr 2024-03-19 14:32:11,151 | ray_client_proxy.py:162 | [36mray::DefaultActor.run()[39m (pid=3898, ip=172.18.144.40, actor_id=efb862ab5f73b1f2b5b4ec9f01000000, repr=<flwr.simulation.ray_transport.ray_actor.DefaultActor object at 0x7f3f30dc6710>)
  File "/home/leon/.local/lib/python3.10/site-packages/flwr/simulation/ray_transport/ray_client_proxy.py", line 225, in evaluate
    return maybe_call_evaluate(
  File "/home/leon/.local/lib/python3.10/site-packages/flwr/client/client.py", line 254, in maybe_call_evaluate
    return client.evaluate(evaluate_ins)
  File "/home/leon/.local/lib/python3.10/site-packages/flwr/client/numpy_client.py", line 262, in _evaluate
    results = self.numpy_client.evaluate(parameters, ins.config)  # type: ignore
  File "/mnt/c/Users/leon1/Documents/Research Repo/Experiments/Ethnicity FL paper/Clients.py", line 36, in evaluate
    loss, accuracy, f1, roc, kappa = test(self.net, self.valloader, DEVICE=self.device, classes=self.net.classes)
  File "/mnt/c/Users/leon1/Documents/Research Repo/Experiments/Ethnicity FL paper/neural_nets.py", line 139, in test
    kappa += multiclass_cohen_kappa(preds, target, num_classes=3)
NameError: name 'preds' is not defined

The above exception was the direct cause of the following exception:

[36mray::DefaultActor.run()[39m (pid=3898, ip=172.18.144.40, actor_id=efb862ab5f73b1f2b5b4ec9f01000000, repr=<flwr.simulation.ray_transport.ray_actor.DefaultActor object at 0x7f3f30dc6710>)
  File "/home/leon/.local/lib/python3.10/site-packages/flwr/simulation/ray_transport/ray_actor.py", line 90, in run
    raise ClientException(str(message)) from ex
flwr.simulation.ray_transport.ray_actor.ClientException: 
>>>>>>>A ClientException occurred.('\n\tSomething went wrong when running your client run.\n\tClient 3 crashed when the DefaultActor was running its run.\n\tException triggered on the client side: Traceback (most recent call last):\n  File "/home/leon/.local/lib/python3.10/site-packages/flwr/simulation/ray_transport/ray_actor.py", line 76, in run\n    job_results = job_fn(client)\n  File "/home/leon/.local/lib/python3.10/site-packages/flwr/simulation/ray_transport/ray_client_proxy.py", line 225, in evaluate\n    return maybe_call_evaluate(\n  File "/home/leon/.local/lib/python3.10/site-packages/flwr/client/client.py", line 254, in maybe_call_evaluate\n    return client.evaluate(evaluate_ins)\n  File "/home/leon/.local/lib/python3.10/site-packages/flwr/client/numpy_client.py", line 262, in _evaluate\n    results = self.numpy_client.evaluate(parameters, ins.config)  # type: ignore\n  File "/mnt/c/Users/leon1/Documents/Research Repo/Experiments/Ethnicity FL paper/Clients.py", line 36, in evaluate\n    loss, accuracy, f1, roc, kappa = test(self.net, self.valloader, DEVICE=self.device, classes=self.net.classes)\n  File "/mnt/c/Users/leon1/Documents/Research Repo/Experiments/Ethnicity FL paper/neural_nets.py", line 139, in test\n    kappa += multiclass_cohen_kappa(preds, target, num_classes=3)\nNameError: name \'preds\' is not defined\n',)
FL Paper Experiment | ERROR flwr 2024-03-19 14:32:12,257 | ray_client_proxy.py:161 | Traceback (most recent call last):
  File "/home/leon/.local/lib/python3.10/site-packages/flwr/simulation/ray_transport/ray_client_proxy.py", line 151, in _submit_job
    res, updated_context = self.actor_pool.get_client_result(self.cid, timeout)
  File "/home/leon/.local/lib/python3.10/site-packages/flwr/simulation/ray_transport/ray_actor.py", line 425, in get_client_result
    return self._fetch_future_result(cid)
  File "/home/leon/.local/lib/python3.10/site-packages/flwr/simulation/ray_transport/ray_actor.py", line 306, in _fetch_future_result
    res_cid, res, updated_context = ray.get(
  File "/home/leon/.local/lib/python3.10/site-packages/ray/_private/auto_init_hook.py", line 24, in auto_init_wrapper
    return fn(*args, **kwargs)
  File "/home/leon/.local/lib/python3.10/site-packages/ray/_private/client_mode_hook.py", line 103, in wrapper
    return func(*args, **kwargs)
  File "/home/leon/.local/lib/python3.10/site-packages/ray/_private/worker.py", line 2524, in get
    raise value.as_instanceof_cause()
ray.exceptions.RayTaskError(ClientException): [36mray::DefaultActor.run()[39m (pid=3898, ip=172.18.144.40, actor_id=efb862ab5f73b1f2b5b4ec9f01000000, repr=<flwr.simulation.ray_transport.ray_actor.DefaultActor object at 0x7f3f30dc6710>)
  File "/home/leon/.local/lib/python3.10/site-packages/flwr/simulation/ray_transport/ray_client_proxy.py", line 225, in evaluate
    return maybe_call_evaluate(
  File "/home/leon/.local/lib/python3.10/site-packages/flwr/client/client.py", line 254, in maybe_call_evaluate
    return client.evaluate(evaluate_ins)
  File "/home/leon/.local/lib/python3.10/site-packages/flwr/client/numpy_client.py", line 262, in _evaluate
    results = self.numpy_client.evaluate(parameters, ins.config)  # type: ignore
  File "/mnt/c/Users/leon1/Documents/Research Repo/Experiments/Ethnicity FL paper/Clients.py", line 36, in evaluate
    loss, accuracy, f1, roc, kappa = test(self.net, self.valloader, DEVICE=self.device, classes=self.net.classes)
  File "/mnt/c/Users/leon1/Documents/Research Repo/Experiments/Ethnicity FL paper/neural_nets.py", line 139, in test
    kappa += multiclass_cohen_kappa(preds, target, num_classes=3)
NameError: name 'preds' is not defined

The above exception was the direct cause of the following exception:

[36mray::DefaultActor.run()[39m (pid=3898, ip=172.18.144.40, actor_id=efb862ab5f73b1f2b5b4ec9f01000000, repr=<flwr.simulation.ray_transport.ray_actor.DefaultActor object at 0x7f3f30dc6710>)
  File "/home/leon/.local/lib/python3.10/site-packages/flwr/simulation/ray_transport/ray_actor.py", line 90, in run
    raise ClientException(str(message)) from ex
flwr.simulation.ray_transport.ray_actor.ClientException: 
>>>>>>>A ClientException occurred.('\n\tSomething went wrong when running your client run.\n\tClient 18 crashed when the DefaultActor was running its run.\n\tException triggered on the client side: Traceback (most recent call last):\n  File "/home/leon/.local/lib/python3.10/site-packages/flwr/simulation/ray_transport/ray_actor.py", line 76, in run\n    job_results = job_fn(client)\n  File "/home/leon/.local/lib/python3.10/site-packages/flwr/simulation/ray_transport/ray_client_proxy.py", line 225, in evaluate\n    return maybe_call_evaluate(\n  File "/home/leon/.local/lib/python3.10/site-packages/flwr/client/client.py", line 254, in maybe_call_evaluate\n    return client.evaluate(evaluate_ins)\n  File "/home/leon/.local/lib/python3.10/site-packages/flwr/client/numpy_client.py", line 262, in _evaluate\n    results = self.numpy_client.evaluate(parameters, ins.config)  # type: ignore\n  File "/mnt/c/Users/leon1/Documents/Research Repo/Experiments/Ethnicity FL paper/Clients.py", line 36, in evaluate\n    loss, accuracy, f1, roc, kappa = test(self.net, self.valloader, DEVICE=self.device, classes=self.net.classes)\n  File "/mnt/c/Users/leon1/Documents/Research Repo/Experiments/Ethnicity FL paper/neural_nets.py", line 139, in test\n    kappa += multiclass_cohen_kappa(preds, target, num_classes=3)\nNameError: name \'preds\' is not defined\n',)

FL Paper Experiment | ERROR flwr 2024-03-19 14:32:12,258 | ray_client_proxy.py:162 | [36mray::DefaultActor.run()[39m (pid=3898, ip=172.18.144.40, actor_id=efb862ab5f73b1f2b5b4ec9f01000000, repr=<flwr.simulation.ray_transport.ray_actor.DefaultActor object at 0x7f3f30dc6710>)
  File "/home/leon/.local/lib/python3.10/site-packages/flwr/simulation/ray_transport/ray_client_proxy.py", line 225, in evaluate
    return maybe_call_evaluate(
  File "/home/leon/.local/lib/python3.10/site-packages/flwr/client/client.py", line 254, in maybe_call_evaluate
    return client.evaluate(evaluate_ins)
  File "/home/leon/.local/lib/python3.10/site-packages/flwr/client/numpy_client.py", line 262, in _evaluate
    results = self.numpy_client.evaluate(parameters, ins.config)  # type: ignore
  File "/mnt/c/Users/leon1/Documents/Research Repo/Experiments/Ethnicity FL paper/Clients.py", line 36, in evaluate
    loss, accuracy, f1, roc, kappa = test(self.net, self.valloader, DEVICE=self.device, classes=self.net.classes)
  File "/mnt/c/Users/leon1/Documents/Research Repo/Experiments/Ethnicity FL paper/neural_nets.py", line 139, in test
    kappa += multiclass_cohen_kappa(preds, target, num_classes=3)
NameError: name 'preds' is not defined

The above exception was the direct cause of the following exception:

[36mray::DefaultActor.run()[39m (pid=3898, ip=172.18.144.40, actor_id=efb862ab5f73b1f2b5b4ec9f01000000, repr=<flwr.simulation.ray_transport.ray_actor.DefaultActor object at 0x7f3f30dc6710>)
  File "/home/leon/.local/lib/python3.10/site-packages/flwr/simulation/ray_transport/ray_actor.py", line 90, in run
    raise ClientException(str(message)) from ex
flwr.simulation.ray_transport.ray_actor.ClientException: 
>>>>>>>A ClientException occurred.('\n\tSomething went wrong when running your client run.\n\tClient 18 crashed when the DefaultActor was running its run.\n\tException triggered on the client side: Traceback (most recent call last):\n  File "/home/leon/.local/lib/python3.10/site-packages/flwr/simulation/ray_transport/ray_actor.py", line 76, in run\n    job_results = job_fn(client)\n  File "/home/leon/.local/lib/python3.10/site-packages/flwr/simulation/ray_transport/ray_client_proxy.py", line 225, in evaluate\n    return maybe_call_evaluate(\n  File "/home/leon/.local/lib/python3.10/site-packages/flwr/client/client.py", line 254, in maybe_call_evaluate\n    return client.evaluate(evaluate_ins)\n  File "/home/leon/.local/lib/python3.10/site-packages/flwr/client/numpy_client.py", line 262, in _evaluate\n    results = self.numpy_client.evaluate(parameters, ins.config)  # type: ignore\n  File "/mnt/c/Users/leon1/Documents/Research Repo/Experiments/Ethnicity FL paper/Clients.py", line 36, in evaluate\n    loss, accuracy, f1, roc, kappa = test(self.net, self.valloader, DEVICE=self.device, classes=self.net.classes)\n  File "/mnt/c/Users/leon1/Documents/Research Repo/Experiments/Ethnicity FL paper/neural_nets.py", line 139, in test\n    kappa += multiclass_cohen_kappa(preds, target, num_classes=3)\nNameError: name \'preds\' is not defined\n',)
FL Paper Experiment | ERROR flwr 2024-03-19 14:32:13,058 | ray_client_proxy.py:161 | Traceback (most recent call last):
  File "/home/leon/.local/lib/python3.10/site-packages/flwr/simulation/ray_transport/ray_client_proxy.py", line 151, in _submit_job
    res, updated_context = self.actor_pool.get_client_result(self.cid, timeout)
  File "/home/leon/.local/lib/python3.10/site-packages/flwr/simulation/ray_transport/ray_actor.py", line 425, in get_client_result
    return self._fetch_future_result(cid)
  File "/home/leon/.local/lib/python3.10/site-packages/flwr/simulation/ray_transport/ray_actor.py", line 306, in _fetch_future_result
    res_cid, res, updated_context = ray.get(
  File "/home/leon/.local/lib/python3.10/site-packages/ray/_private/auto_init_hook.py", line 24, in auto_init_wrapper
    return fn(*args, **kwargs)
  File "/home/leon/.local/lib/python3.10/site-packages/ray/_private/client_mode_hook.py", line 103, in wrapper
    return func(*args, **kwargs)
  File "/home/leon/.local/lib/python3.10/site-packages/ray/_private/worker.py", line 2524, in get
    raise value.as_instanceof_cause()
ray.exceptions.RayTaskError(ClientException): [36mray::DefaultActor.run()[39m (pid=3898, ip=172.18.144.40, actor_id=efb862ab5f73b1f2b5b4ec9f01000000, repr=<flwr.simulation.ray_transport.ray_actor.DefaultActor object at 0x7f3f30dc6710>)
  File "/home/leon/.local/lib/python3.10/site-packages/flwr/simulation/ray_transport/ray_client_proxy.py", line 225, in evaluate
    return maybe_call_evaluate(
  File "/home/leon/.local/lib/python3.10/site-packages/flwr/client/client.py", line 254, in maybe_call_evaluate
    return client.evaluate(evaluate_ins)
  File "/home/leon/.local/lib/python3.10/site-packages/flwr/client/numpy_client.py", line 262, in _evaluate
    results = self.numpy_client.evaluate(parameters, ins.config)  # type: ignore
  File "/mnt/c/Users/leon1/Documents/Research Repo/Experiments/Ethnicity FL paper/Clients.py", line 36, in evaluate
    loss, accuracy, f1, roc, kappa = test(self.net, self.valloader, DEVICE=self.device, classes=self.net.classes)
  File "/mnt/c/Users/leon1/Documents/Research Repo/Experiments/Ethnicity FL paper/neural_nets.py", line 139, in test
    kappa += multiclass_cohen_kappa(preds, target, num_classes=3)
NameError: name 'preds' is not defined

The above exception was the direct cause of the following exception:

[36mray::DefaultActor.run()[39m (pid=3898, ip=172.18.144.40, actor_id=efb862ab5f73b1f2b5b4ec9f01000000, repr=<flwr.simulation.ray_transport.ray_actor.DefaultActor object at 0x7f3f30dc6710>)
  File "/home/leon/.local/lib/python3.10/site-packages/flwr/simulation/ray_transport/ray_actor.py", line 90, in run
    raise ClientException(str(message)) from ex
flwr.simulation.ray_transport.ray_actor.ClientException: 
>>>>>>>A ClientException occurred.('\n\tSomething went wrong when running your client run.\n\tClient 17 crashed when the DefaultActor was running its run.\n\tException triggered on the client side: Traceback (most recent call last):\n  File "/home/leon/.local/lib/python3.10/site-packages/flwr/simulation/ray_transport/ray_actor.py", line 76, in run\n    job_results = job_fn(client)\n  File "/home/leon/.local/lib/python3.10/site-packages/flwr/simulation/ray_transport/ray_client_proxy.py", line 225, in evaluate\n    return maybe_call_evaluate(\n  File "/home/leon/.local/lib/python3.10/site-packages/flwr/client/client.py", line 254, in maybe_call_evaluate\n    return client.evaluate(evaluate_ins)\n  File "/home/leon/.local/lib/python3.10/site-packages/flwr/client/numpy_client.py", line 262, in _evaluate\n    results = self.numpy_client.evaluate(parameters, ins.config)  # type: ignore\n  File "/mnt/c/Users/leon1/Documents/Research Repo/Experiments/Ethnicity FL paper/Clients.py", line 36, in evaluate\n    loss, accuracy, f1, roc, kappa = test(self.net, self.valloader, DEVICE=self.device, classes=self.net.classes)\n  File "/mnt/c/Users/leon1/Documents/Research Repo/Experiments/Ethnicity FL paper/neural_nets.py", line 139, in test\n    kappa += multiclass_cohen_kappa(preds, target, num_classes=3)\nNameError: name \'preds\' is not defined\n',)

FL Paper Experiment | ERROR flwr 2024-03-19 14:32:13,059 | ray_client_proxy.py:162 | [36mray::DefaultActor.run()[39m (pid=3898, ip=172.18.144.40, actor_id=efb862ab5f73b1f2b5b4ec9f01000000, repr=<flwr.simulation.ray_transport.ray_actor.DefaultActor object at 0x7f3f30dc6710>)
  File "/home/leon/.local/lib/python3.10/site-packages/flwr/simulation/ray_transport/ray_client_proxy.py", line 225, in evaluate
    return maybe_call_evaluate(
  File "/home/leon/.local/lib/python3.10/site-packages/flwr/client/client.py", line 254, in maybe_call_evaluate
    return client.evaluate(evaluate_ins)
  File "/home/leon/.local/lib/python3.10/site-packages/flwr/client/numpy_client.py", line 262, in _evaluate
    results = self.numpy_client.evaluate(parameters, ins.config)  # type: ignore
  File "/mnt/c/Users/leon1/Documents/Research Repo/Experiments/Ethnicity FL paper/Clients.py", line 36, in evaluate
    loss, accuracy, f1, roc, kappa = test(self.net, self.valloader, DEVICE=self.device, classes=self.net.classes)
  File "/mnt/c/Users/leon1/Documents/Research Repo/Experiments/Ethnicity FL paper/neural_nets.py", line 139, in test
    kappa += multiclass_cohen_kappa(preds, target, num_classes=3)
NameError: name 'preds' is not defined

The above exception was the direct cause of the following exception:

[36mray::DefaultActor.run()[39m (pid=3898, ip=172.18.144.40, actor_id=efb862ab5f73b1f2b5b4ec9f01000000, repr=<flwr.simulation.ray_transport.ray_actor.DefaultActor object at 0x7f3f30dc6710>)
  File "/home/leon/.local/lib/python3.10/site-packages/flwr/simulation/ray_transport/ray_actor.py", line 90, in run
    raise ClientException(str(message)) from ex
flwr.simulation.ray_transport.ray_actor.ClientException: 
>>>>>>>A ClientException occurred.('\n\tSomething went wrong when running your client run.\n\tClient 17 crashed when the DefaultActor was running its run.\n\tException triggered on the client side: Traceback (most recent call last):\n  File "/home/leon/.local/lib/python3.10/site-packages/flwr/simulation/ray_transport/ray_actor.py", line 76, in run\n    job_results = job_fn(client)\n  File "/home/leon/.local/lib/python3.10/site-packages/flwr/simulation/ray_transport/ray_client_proxy.py", line 225, in evaluate\n    return maybe_call_evaluate(\n  File "/home/leon/.local/lib/python3.10/site-packages/flwr/client/client.py", line 254, in maybe_call_evaluate\n    return client.evaluate(evaluate_ins)\n  File "/home/leon/.local/lib/python3.10/site-packages/flwr/client/numpy_client.py", line 262, in _evaluate\n    results = self.numpy_client.evaluate(parameters, ins.config)  # type: ignore\n  File "/mnt/c/Users/leon1/Documents/Research Repo/Experiments/Ethnicity FL paper/Clients.py", line 36, in evaluate\n    loss, accuracy, f1, roc, kappa = test(self.net, self.valloader, DEVICE=self.device, classes=self.net.classes)\n  File "/mnt/c/Users/leon1/Documents/Research Repo/Experiments/Ethnicity FL paper/neural_nets.py", line 139, in test\n    kappa += multiclass_cohen_kappa(preds, target, num_classes=3)\nNameError: name \'preds\' is not defined\n',)
FL Paper Experiment | ERROR flwr 2024-03-19 14:32:13,948 | ray_client_proxy.py:161 | Traceback (most recent call last):
  File "/home/leon/.local/lib/python3.10/site-packages/flwr/simulation/ray_transport/ray_client_proxy.py", line 151, in _submit_job
    res, updated_context = self.actor_pool.get_client_result(self.cid, timeout)
  File "/home/leon/.local/lib/python3.10/site-packages/flwr/simulation/ray_transport/ray_actor.py", line 425, in get_client_result
    return self._fetch_future_result(cid)
  File "/home/leon/.local/lib/python3.10/site-packages/flwr/simulation/ray_transport/ray_actor.py", line 306, in _fetch_future_result
    res_cid, res, updated_context = ray.get(
  File "/home/leon/.local/lib/python3.10/site-packages/ray/_private/auto_init_hook.py", line 24, in auto_init_wrapper
    return fn(*args, **kwargs)
  File "/home/leon/.local/lib/python3.10/site-packages/ray/_private/client_mode_hook.py", line 103, in wrapper
    return func(*args, **kwargs)
  File "/home/leon/.local/lib/python3.10/site-packages/ray/_private/worker.py", line 2524, in get
    raise value.as_instanceof_cause()
ray.exceptions.RayTaskError(ClientException): [36mray::DefaultActor.run()[39m (pid=3898, ip=172.18.144.40, actor_id=efb862ab5f73b1f2b5b4ec9f01000000, repr=<flwr.simulation.ray_transport.ray_actor.DefaultActor object at 0x7f3f30dc6710>)
  File "/home/leon/.local/lib/python3.10/site-packages/flwr/simulation/ray_transport/ray_client_proxy.py", line 225, in evaluate
    return maybe_call_evaluate(
  File "/home/leon/.local/lib/python3.10/site-packages/flwr/client/client.py", line 254, in maybe_call_evaluate
    return client.evaluate(evaluate_ins)
  File "/home/leon/.local/lib/python3.10/site-packages/flwr/client/numpy_client.py", line 262, in _evaluate
    results = self.numpy_client.evaluate(parameters, ins.config)  # type: ignore
  File "/mnt/c/Users/leon1/Documents/Research Repo/Experiments/Ethnicity FL paper/Clients.py", line 36, in evaluate
    loss, accuracy, f1, roc, kappa = test(self.net, self.valloader, DEVICE=self.device, classes=self.net.classes)
  File "/mnt/c/Users/leon1/Documents/Research Repo/Experiments/Ethnicity FL paper/neural_nets.py", line 139, in test
    kappa += multiclass_cohen_kappa(preds, target, num_classes=3)
NameError: name 'preds' is not defined

The above exception was the direct cause of the following exception:

[36mray::DefaultActor.run()[39m (pid=3898, ip=172.18.144.40, actor_id=efb862ab5f73b1f2b5b4ec9f01000000, repr=<flwr.simulation.ray_transport.ray_actor.DefaultActor object at 0x7f3f30dc6710>)
  File "/home/leon/.local/lib/python3.10/site-packages/flwr/simulation/ray_transport/ray_actor.py", line 90, in run
    raise ClientException(str(message)) from ex
flwr.simulation.ray_transport.ray_actor.ClientException: 
>>>>>>>A ClientException occurred.('\n\tSomething went wrong when running your client run.\n\tClient 11 crashed when the DefaultActor was running its run.\n\tException triggered on the client side: Traceback (most recent call last):\n  File "/home/leon/.local/lib/python3.10/site-packages/flwr/simulation/ray_transport/ray_actor.py", line 76, in run\n    job_results = job_fn(client)\n  File "/home/leon/.local/lib/python3.10/site-packages/flwr/simulation/ray_transport/ray_client_proxy.py", line 225, in evaluate\n    return maybe_call_evaluate(\n  File "/home/leon/.local/lib/python3.10/site-packages/flwr/client/client.py", line 254, in maybe_call_evaluate\n    return client.evaluate(evaluate_ins)\n  File "/home/leon/.local/lib/python3.10/site-packages/flwr/client/numpy_client.py", line 262, in _evaluate\n    results = self.numpy_client.evaluate(parameters, ins.config)  # type: ignore\n  File "/mnt/c/Users/leon1/Documents/Research Repo/Experiments/Ethnicity FL paper/Clients.py", line 36, in evaluate\n    loss, accuracy, f1, roc, kappa = test(self.net, self.valloader, DEVICE=self.device, classes=self.net.classes)\n  File "/mnt/c/Users/leon1/Documents/Research Repo/Experiments/Ethnicity FL paper/neural_nets.py", line 139, in test\n    kappa += multiclass_cohen_kappa(preds, target, num_classes=3)\nNameError: name \'preds\' is not defined\n',)

FL Paper Experiment | ERROR flwr 2024-03-19 14:32:13,948 | ray_client_proxy.py:162 | [36mray::DefaultActor.run()[39m (pid=3898, ip=172.18.144.40, actor_id=efb862ab5f73b1f2b5b4ec9f01000000, repr=<flwr.simulation.ray_transport.ray_actor.DefaultActor object at 0x7f3f30dc6710>)
  File "/home/leon/.local/lib/python3.10/site-packages/flwr/simulation/ray_transport/ray_client_proxy.py", line 225, in evaluate
    return maybe_call_evaluate(
  File "/home/leon/.local/lib/python3.10/site-packages/flwr/client/client.py", line 254, in maybe_call_evaluate
    return client.evaluate(evaluate_ins)
  File "/home/leon/.local/lib/python3.10/site-packages/flwr/client/numpy_client.py", line 262, in _evaluate
    results = self.numpy_client.evaluate(parameters, ins.config)  # type: ignore
  File "/mnt/c/Users/leon1/Documents/Research Repo/Experiments/Ethnicity FL paper/Clients.py", line 36, in evaluate
    loss, accuracy, f1, roc, kappa = test(self.net, self.valloader, DEVICE=self.device, classes=self.net.classes)
  File "/mnt/c/Users/leon1/Documents/Research Repo/Experiments/Ethnicity FL paper/neural_nets.py", line 139, in test
    kappa += multiclass_cohen_kappa(preds, target, num_classes=3)
NameError: name 'preds' is not defined

The above exception was the direct cause of the following exception:

[36mray::DefaultActor.run()[39m (pid=3898, ip=172.18.144.40, actor_id=efb862ab5f73b1f2b5b4ec9f01000000, repr=<flwr.simulation.ray_transport.ray_actor.DefaultActor object at 0x7f3f30dc6710>)
  File "/home/leon/.local/lib/python3.10/site-packages/flwr/simulation/ray_transport/ray_actor.py", line 90, in run
    raise ClientException(str(message)) from ex
flwr.simulation.ray_transport.ray_actor.ClientException: 
>>>>>>>A ClientException occurred.('\n\tSomething went wrong when running your client run.\n\tClient 11 crashed when the DefaultActor was running its run.\n\tException triggered on the client side: Traceback (most recent call last):\n  File "/home/leon/.local/lib/python3.10/site-packages/flwr/simulation/ray_transport/ray_actor.py", line 76, in run\n    job_results = job_fn(client)\n  File "/home/leon/.local/lib/python3.10/site-packages/flwr/simulation/ray_transport/ray_client_proxy.py", line 225, in evaluate\n    return maybe_call_evaluate(\n  File "/home/leon/.local/lib/python3.10/site-packages/flwr/client/client.py", line 254, in maybe_call_evaluate\n    return client.evaluate(evaluate_ins)\n  File "/home/leon/.local/lib/python3.10/site-packages/flwr/client/numpy_client.py", line 262, in _evaluate\n    results = self.numpy_client.evaluate(parameters, ins.config)  # type: ignore\n  File "/mnt/c/Users/leon1/Documents/Research Repo/Experiments/Ethnicity FL paper/Clients.py", line 36, in evaluate\n    loss, accuracy, f1, roc, kappa = test(self.net, self.valloader, DEVICE=self.device, classes=self.net.classes)\n  File "/mnt/c/Users/leon1/Documents/Research Repo/Experiments/Ethnicity FL paper/neural_nets.py", line 139, in test\n    kappa += multiclass_cohen_kappa(preds, target, num_classes=3)\nNameError: name \'preds\' is not defined\n',)
FL Paper Experiment | ERROR flwr 2024-03-19 14:32:14,712 | ray_client_proxy.py:161 | Traceback (most recent call last):
  File "/home/leon/.local/lib/python3.10/site-packages/flwr/simulation/ray_transport/ray_client_proxy.py", line 151, in _submit_job
    res, updated_context = self.actor_pool.get_client_result(self.cid, timeout)
  File "/home/leon/.local/lib/python3.10/site-packages/flwr/simulation/ray_transport/ray_actor.py", line 425, in get_client_result
    return self._fetch_future_result(cid)
  File "/home/leon/.local/lib/python3.10/site-packages/flwr/simulation/ray_transport/ray_actor.py", line 306, in _fetch_future_result
    res_cid, res, updated_context = ray.get(
  File "/home/leon/.local/lib/python3.10/site-packages/ray/_private/auto_init_hook.py", line 24, in auto_init_wrapper
    return fn(*args, **kwargs)
  File "/home/leon/.local/lib/python3.10/site-packages/ray/_private/client_mode_hook.py", line 103, in wrapper
    return func(*args, **kwargs)
  File "/home/leon/.local/lib/python3.10/site-packages/ray/_private/worker.py", line 2524, in get
    raise value.as_instanceof_cause()
ray.exceptions.RayTaskError(ClientException): [36mray::DefaultActor.run()[39m (pid=3898, ip=172.18.144.40, actor_id=efb862ab5f73b1f2b5b4ec9f01000000, repr=<flwr.simulation.ray_transport.ray_actor.DefaultActor object at 0x7f3f30dc6710>)
  File "/home/leon/.local/lib/python3.10/site-packages/flwr/simulation/ray_transport/ray_client_proxy.py", line 225, in evaluate
    return maybe_call_evaluate(
  File "/home/leon/.local/lib/python3.10/site-packages/flwr/client/client.py", line 254, in maybe_call_evaluate
    return client.evaluate(evaluate_ins)
  File "/home/leon/.local/lib/python3.10/site-packages/flwr/client/numpy_client.py", line 262, in _evaluate
    results = self.numpy_client.evaluate(parameters, ins.config)  # type: ignore
  File "/mnt/c/Users/leon1/Documents/Research Repo/Experiments/Ethnicity FL paper/Clients.py", line 36, in evaluate
    loss, accuracy, f1, roc, kappa = test(self.net, self.valloader, DEVICE=self.device, classes=self.net.classes)
  File "/mnt/c/Users/leon1/Documents/Research Repo/Experiments/Ethnicity FL paper/neural_nets.py", line 139, in test
    kappa += multiclass_cohen_kappa(preds, target, num_classes=3)
NameError: name 'preds' is not defined

The above exception was the direct cause of the following exception:

[36mray::DefaultActor.run()[39m (pid=3898, ip=172.18.144.40, actor_id=efb862ab5f73b1f2b5b4ec9f01000000, repr=<flwr.simulation.ray_transport.ray_actor.DefaultActor object at 0x7f3f30dc6710>)
  File "/home/leon/.local/lib/python3.10/site-packages/flwr/simulation/ray_transport/ray_actor.py", line 90, in run
    raise ClientException(str(message)) from ex
flwr.simulation.ray_transport.ray_actor.ClientException: 
>>>>>>>A ClientException occurred.('\n\tSomething went wrong when running your client run.\n\tClient 10 crashed when the DefaultActor was running its run.\n\tException triggered on the client side: Traceback (most recent call last):\n  File "/home/leon/.local/lib/python3.10/site-packages/flwr/simulation/ray_transport/ray_actor.py", line 76, in run\n    job_results = job_fn(client)\n  File "/home/leon/.local/lib/python3.10/site-packages/flwr/simulation/ray_transport/ray_client_proxy.py", line 225, in evaluate\n    return maybe_call_evaluate(\n  File "/home/leon/.local/lib/python3.10/site-packages/flwr/client/client.py", line 254, in maybe_call_evaluate\n    return client.evaluate(evaluate_ins)\n  File "/home/leon/.local/lib/python3.10/site-packages/flwr/client/numpy_client.py", line 262, in _evaluate\n    results = self.numpy_client.evaluate(parameters, ins.config)  # type: ignore\n  File "/mnt/c/Users/leon1/Documents/Research Repo/Experiments/Ethnicity FL paper/Clients.py", line 36, in evaluate\n    loss, accuracy, f1, roc, kappa = test(self.net, self.valloader, DEVICE=self.device, classes=self.net.classes)\n  File "/mnt/c/Users/leon1/Documents/Research Repo/Experiments/Ethnicity FL paper/neural_nets.py", line 139, in test\n    kappa += multiclass_cohen_kappa(preds, target, num_classes=3)\nNameError: name \'preds\' is not defined\n',)

FL Paper Experiment | ERROR flwr 2024-03-19 14:32:14,713 | ray_client_proxy.py:162 | [36mray::DefaultActor.run()[39m (pid=3898, ip=172.18.144.40, actor_id=efb862ab5f73b1f2b5b4ec9f01000000, repr=<flwr.simulation.ray_transport.ray_actor.DefaultActor object at 0x7f3f30dc6710>)
  File "/home/leon/.local/lib/python3.10/site-packages/flwr/simulation/ray_transport/ray_client_proxy.py", line 225, in evaluate
    return maybe_call_evaluate(
  File "/home/leon/.local/lib/python3.10/site-packages/flwr/client/client.py", line 254, in maybe_call_evaluate
    return client.evaluate(evaluate_ins)
  File "/home/leon/.local/lib/python3.10/site-packages/flwr/client/numpy_client.py", line 262, in _evaluate
    results = self.numpy_client.evaluate(parameters, ins.config)  # type: ignore
  File "/mnt/c/Users/leon1/Documents/Research Repo/Experiments/Ethnicity FL paper/Clients.py", line 36, in evaluate
    loss, accuracy, f1, roc, kappa = test(self.net, self.valloader, DEVICE=self.device, classes=self.net.classes)
  File "/mnt/c/Users/leon1/Documents/Research Repo/Experiments/Ethnicity FL paper/neural_nets.py", line 139, in test
    kappa += multiclass_cohen_kappa(preds, target, num_classes=3)
NameError: name 'preds' is not defined

The above exception was the direct cause of the following exception:

[36mray::DefaultActor.run()[39m (pid=3898, ip=172.18.144.40, actor_id=efb862ab5f73b1f2b5b4ec9f01000000, repr=<flwr.simulation.ray_transport.ray_actor.DefaultActor object at 0x7f3f30dc6710>)
  File "/home/leon/.local/lib/python3.10/site-packages/flwr/simulation/ray_transport/ray_actor.py", line 90, in run
    raise ClientException(str(message)) from ex
flwr.simulation.ray_transport.ray_actor.ClientException: 
>>>>>>>A ClientException occurred.('\n\tSomething went wrong when running your client run.\n\tClient 10 crashed when the DefaultActor was running its run.\n\tException triggered on the client side: Traceback (most recent call last):\n  File "/home/leon/.local/lib/python3.10/site-packages/flwr/simulation/ray_transport/ray_actor.py", line 76, in run\n    job_results = job_fn(client)\n  File "/home/leon/.local/lib/python3.10/site-packages/flwr/simulation/ray_transport/ray_client_proxy.py", line 225, in evaluate\n    return maybe_call_evaluate(\n  File "/home/leon/.local/lib/python3.10/site-packages/flwr/client/client.py", line 254, in maybe_call_evaluate\n    return client.evaluate(evaluate_ins)\n  File "/home/leon/.local/lib/python3.10/site-packages/flwr/client/numpy_client.py", line 262, in _evaluate\n    results = self.numpy_client.evaluate(parameters, ins.config)  # type: ignore\n  File "/mnt/c/Users/leon1/Documents/Research Repo/Experiments/Ethnicity FL paper/Clients.py", line 36, in evaluate\n    loss, accuracy, f1, roc, kappa = test(self.net, self.valloader, DEVICE=self.device, classes=self.net.classes)\n  File "/mnt/c/Users/leon1/Documents/Research Repo/Experiments/Ethnicity FL paper/neural_nets.py", line 139, in test\n    kappa += multiclass_cohen_kappa(preds, target, num_classes=3)\nNameError: name \'preds\' is not defined\n',)
FL Paper Experiment | ERROR flwr 2024-03-19 14:32:15,453 | ray_client_proxy.py:161 | Traceback (most recent call last):
  File "/home/leon/.local/lib/python3.10/site-packages/flwr/simulation/ray_transport/ray_client_proxy.py", line 151, in _submit_job
    res, updated_context = self.actor_pool.get_client_result(self.cid, timeout)
  File "/home/leon/.local/lib/python3.10/site-packages/flwr/simulation/ray_transport/ray_actor.py", line 425, in get_client_result
    return self._fetch_future_result(cid)
  File "/home/leon/.local/lib/python3.10/site-packages/flwr/simulation/ray_transport/ray_actor.py", line 306, in _fetch_future_result
    res_cid, res, updated_context = ray.get(
  File "/home/leon/.local/lib/python3.10/site-packages/ray/_private/auto_init_hook.py", line 24, in auto_init_wrapper
    return fn(*args, **kwargs)
  File "/home/leon/.local/lib/python3.10/site-packages/ray/_private/client_mode_hook.py", line 103, in wrapper
    return func(*args, **kwargs)
  File "/home/leon/.local/lib/python3.10/site-packages/ray/_private/worker.py", line 2524, in get
    raise value.as_instanceof_cause()
ray.exceptions.RayTaskError(ClientException): [36mray::DefaultActor.run()[39m (pid=3898, ip=172.18.144.40, actor_id=efb862ab5f73b1f2b5b4ec9f01000000, repr=<flwr.simulation.ray_transport.ray_actor.DefaultActor object at 0x7f3f30dc6710>)
  File "/home/leon/.local/lib/python3.10/site-packages/flwr/simulation/ray_transport/ray_client_proxy.py", line 225, in evaluate
    return maybe_call_evaluate(
  File "/home/leon/.local/lib/python3.10/site-packages/flwr/client/client.py", line 254, in maybe_call_evaluate
    return client.evaluate(evaluate_ins)
  File "/home/leon/.local/lib/python3.10/site-packages/flwr/client/numpy_client.py", line 262, in _evaluate
    results = self.numpy_client.evaluate(parameters, ins.config)  # type: ignore
  File "/mnt/c/Users/leon1/Documents/Research Repo/Experiments/Ethnicity FL paper/Clients.py", line 36, in evaluate
    loss, accuracy, f1, roc, kappa = test(self.net, self.valloader, DEVICE=self.device, classes=self.net.classes)
  File "/mnt/c/Users/leon1/Documents/Research Repo/Experiments/Ethnicity FL paper/neural_nets.py", line 139, in test
    kappa += multiclass_cohen_kappa(preds, target, num_classes=3)
NameError: name 'preds' is not defined

The above exception was the direct cause of the following exception:

[36mray::DefaultActor.run()[39m (pid=3898, ip=172.18.144.40, actor_id=efb862ab5f73b1f2b5b4ec9f01000000, repr=<flwr.simulation.ray_transport.ray_actor.DefaultActor object at 0x7f3f30dc6710>)
  File "/home/leon/.local/lib/python3.10/site-packages/flwr/simulation/ray_transport/ray_actor.py", line 90, in run
    raise ClientException(str(message)) from ex
flwr.simulation.ray_transport.ray_actor.ClientException: 
>>>>>>>A ClientException occurred.('\n\tSomething went wrong when running your client run.\n\tClient 0 crashed when the DefaultActor was running its run.\n\tException triggered on the client side: Traceback (most recent call last):\n  File "/home/leon/.local/lib/python3.10/site-packages/flwr/simulation/ray_transport/ray_actor.py", line 76, in run\n    job_results = job_fn(client)\n  File "/home/leon/.local/lib/python3.10/site-packages/flwr/simulation/ray_transport/ray_client_proxy.py", line 225, in evaluate\n    return maybe_call_evaluate(\n  File "/home/leon/.local/lib/python3.10/site-packages/flwr/client/client.py", line 254, in maybe_call_evaluate\n    return client.evaluate(evaluate_ins)\n  File "/home/leon/.local/lib/python3.10/site-packages/flwr/client/numpy_client.py", line 262, in _evaluate\n    results = self.numpy_client.evaluate(parameters, ins.config)  # type: ignore\n  File "/mnt/c/Users/leon1/Documents/Research Repo/Experiments/Ethnicity FL paper/Clients.py", line 36, in evaluate\n    loss, accuracy, f1, roc, kappa = test(self.net, self.valloader, DEVICE=self.device, classes=self.net.classes)\n  File "/mnt/c/Users/leon1/Documents/Research Repo/Experiments/Ethnicity FL paper/neural_nets.py", line 139, in test\n    kappa += multiclass_cohen_kappa(preds, target, num_classes=3)\nNameError: name \'preds\' is not defined\n',)

FL Paper Experiment | ERROR flwr 2024-03-19 14:32:15,454 | ray_client_proxy.py:162 | [36mray::DefaultActor.run()[39m (pid=3898, ip=172.18.144.40, actor_id=efb862ab5f73b1f2b5b4ec9f01000000, repr=<flwr.simulation.ray_transport.ray_actor.DefaultActor object at 0x7f3f30dc6710>)
  File "/home/leon/.local/lib/python3.10/site-packages/flwr/simulation/ray_transport/ray_client_proxy.py", line 225, in evaluate
    return maybe_call_evaluate(
  File "/home/leon/.local/lib/python3.10/site-packages/flwr/client/client.py", line 254, in maybe_call_evaluate
    return client.evaluate(evaluate_ins)
  File "/home/leon/.local/lib/python3.10/site-packages/flwr/client/numpy_client.py", line 262, in _evaluate
    results = self.numpy_client.evaluate(parameters, ins.config)  # type: ignore
  File "/mnt/c/Users/leon1/Documents/Research Repo/Experiments/Ethnicity FL paper/Clients.py", line 36, in evaluate
    loss, accuracy, f1, roc, kappa = test(self.net, self.valloader, DEVICE=self.device, classes=self.net.classes)
  File "/mnt/c/Users/leon1/Documents/Research Repo/Experiments/Ethnicity FL paper/neural_nets.py", line 139, in test
    kappa += multiclass_cohen_kappa(preds, target, num_classes=3)
NameError: name 'preds' is not defined

The above exception was the direct cause of the following exception:

[36mray::DefaultActor.run()[39m (pid=3898, ip=172.18.144.40, actor_id=efb862ab5f73b1f2b5b4ec9f01000000, repr=<flwr.simulation.ray_transport.ray_actor.DefaultActor object at 0x7f3f30dc6710>)
  File "/home/leon/.local/lib/python3.10/site-packages/flwr/simulation/ray_transport/ray_actor.py", line 90, in run
    raise ClientException(str(message)) from ex
flwr.simulation.ray_transport.ray_actor.ClientException: 
>>>>>>>A ClientException occurred.('\n\tSomething went wrong when running your client run.\n\tClient 0 crashed when the DefaultActor was running its run.\n\tException triggered on the client side: Traceback (most recent call last):\n  File "/home/leon/.local/lib/python3.10/site-packages/flwr/simulation/ray_transport/ray_actor.py", line 76, in run\n    job_results = job_fn(client)\n  File "/home/leon/.local/lib/python3.10/site-packages/flwr/simulation/ray_transport/ray_client_proxy.py", line 225, in evaluate\n    return maybe_call_evaluate(\n  File "/home/leon/.local/lib/python3.10/site-packages/flwr/client/client.py", line 254, in maybe_call_evaluate\n    return client.evaluate(evaluate_ins)\n  File "/home/leon/.local/lib/python3.10/site-packages/flwr/client/numpy_client.py", line 262, in _evaluate\n    results = self.numpy_client.evaluate(parameters, ins.config)  # type: ignore\n  File "/mnt/c/Users/leon1/Documents/Research Repo/Experiments/Ethnicity FL paper/Clients.py", line 36, in evaluate\n    loss, accuracy, f1, roc, kappa = test(self.net, self.valloader, DEVICE=self.device, classes=self.net.classes)\n  File "/mnt/c/Users/leon1/Documents/Research Repo/Experiments/Ethnicity FL paper/neural_nets.py", line 139, in test\n    kappa += multiclass_cohen_kappa(preds, target, num_classes=3)\nNameError: name \'preds\' is not defined\n',)
